// Teste funcional simples para validar a corre√ß√£o do TypeError
// Este teste simula o cen√°rio original que causava o erro

// import { getAlertCacheMetrics } from '../utils/optimizedAlerts'; // Not used in current test

// Simular dados corrompidos que poderiam vir da fun√ß√£o getAlertCacheMetrics
const testScenarios = [
  { name: 'undefined cacheKeys', data: { alertCacheSize: 5, cacheKeys: undefined } },
  { name: 'null cacheKeys', data: { alertCacheSize: 3, cacheKeys: null } },
  { name: 'empty array', data: { alertCacheSize: 0, cacheKeys: [] } },
  { name: 'valid array', data: { alertCacheSize: 2, cacheKeys: ['key1', 'key2'] } },
  { name: 'undefined object', data: undefined },
  { name: 'null object', data: null }
];

// console.log('üß™ Testando cen√°rios que causavam TypeError...\n');

testScenarios.forEach(scenario => {
  try {
    // console.log(`üìã Cen√°rio: ${scenario.name}`);
    
    // Simular o que aconteceria no componente
    const alertMetrics = scenario.data;
    
    // Fun√ß√£o helper do componente - mesma implementa√ß√£o
    const safeArrayAccess = function<T>(array: T[] | undefined | null): T[] {
      return Array.isArray(array) ? array : [];
    };
    
    // Valida√ß√µes que eram aplicadas no componente original (sem corre√ß√£o)
    // console.log('  ‚ùå C√≥digo original teria falhado aqui:');
    try {
      // Esta linha causava o erro original
      // const length = alertMetrics.cacheKeys.length; // TypeError!
      // console.log('    - alertMetrics.cacheKeys.length teria causado TypeError');
    } catch {
      // console.log(`    - Erro capturado: ${e}`);
    }
    
    // Valida√ß√µes com a corre√ß√£o aplicada
    // console.log('  ‚úÖ C√≥digo corrigido:');
    const _alertCacheSize = alertMetrics?.alertCacheSize ?? 0;
    const _cacheKeysLength = safeArrayAccess(alertMetrics?.cacheKeys).length;
    
    // console.log(`    - alertCacheSize: ${alertCacheSize}`);
    // console.log(`    - cacheKeys.length: ${cacheKeysLength}`);
    // console.log('    - ‚úÖ Sucesso! Sem errors\n');
    
  } catch (error) {
    console.error(`  ‚ùå Falha inesperada: ${error}\n`);
  }
});

// console.log('üéâ Todos os cen√°rios foram tratados com seguran√ßa!');